Workbook

Sheet Stock Prices
A1: Date | B1: Ticker | C1: Company Name | D1: Close Price | E1: High Price | F1: Low Price | G1: return on stocks | H1: Market Return | I1: Risk Free rate | J1: Excess Return | K1: Market Excess return
A2: 2019-01 | B2: AAPL | C2: APPLE INC | D2: =Sheet1!A1/4 -> 41.61 | E2: 169 | F2: 142 | H2: =VLOOKUP(A2,Table2[],3, FALSE) -> 0 | I2: =VLOOKUP(A2,Table3[],3, FALSE) -> 0.0019783315 | J2: =G2-I2 -> -0.0019783315 | K2: =H2-I2 -> -0.0019783315
A3: 2019-02 | B3: AAPL | C3: APPLE INC | D3: =Sheet1!A2/4 -> 43.2875 | E3: 175.87 | F3: 165.93 | G3: =(D3-D2)/D2 -> 0.040314828 | H3: =VLOOKUP(A3,Table2[],3, FALSE) -> 0.02972893 | I3: =VLOOKUP(A3,Table3[],3, FALSE) -> 0.0020027906 | J3: =G3-I3 -> 0.038312038 | K3: =H3-I3 -> 0.02772614
A4: 2019-03 | B4: AAPL | C4: APPLE INC | D4: =Sheet1!A3/4 -> 47.4875 | E4: 197.69 | F4: 169.5 | G4: =(D4-D3)/D3 -> 0.0970257 | H4: =VLOOKUP(A4,Table2[],3, FALSE) -> 0.017924288 | I4: =VLOOKUP(A4,Table3[],3, FALSE) -> 0.002019093 | J4: =G4-I4 -> 0.095006607 | K4: =H4-I4 -> 0.015905195
A5: 2019-04 | B5: AAPL | C5: APPLE INC | D5: =Sheet1!A4/4 -> 50.1675 | E5: 208.48 | F5: 188.38 | G5: =(D5-D4)/D4 -> 0.056435904 | H5: =VLOOKUP(A5,Table2[],3, FALSE) -> 0.039313435 | I5: =VLOOKUP(A5,Table3[],3, FALSE) -> 0.0020027906 | J5: =G5-I5 -> 0.054433114 | K5: =H5-I5 -> 0.037310644
A6: 2019-05 | B6: AAPL | C6: APPLE INC | D6: =Sheet1!A5/4 -> 43.7675 | E6: 215.31 | F6: 174.99 | G6: =(D6-D5)/D5 -> -0.12757263 | H6: =VLOOKUP(A6,Table2[],3, FALSE) -> -0.065777726 | I6: =VLOOKUP(A6,Table3[],3, FALSE) -> 0.0019783315 | J6: =G6-I6 -> -0.12955096 | K6: =H6-I6 -> -0.067756058
A7: 2019-06 | B7: AAPL | C7: APPLE INC | D7: =Sheet1!A6/4 -> 49.48 | E7: 201.57 | F7: 170.27 | G7: =(D7-D6)/D6 -> 0.13051922 | H7: =VLOOKUP(A7,Table2[],3, FALSE) -> 0.068930183 | I7: =VLOOKUP(A7,Table3[],3, FALSE) -> 0.001831439 | J7: =G7-I7 -> 0.12868778 | K7: =H7-I7 -> 0.067098744
A8: 2019-07 | B8: AAPL | C8: APPLE INC | D8: =Sheet1!A7/4 -> 53.26 | E8: 221.37 | F8: 198.41 | G8: =(D8-D7)/D7 -> 0.076394503 | H8: =VLOOKUP(A8,Table2[],3, FALSE) -> 0.013128195 | I8: =VLOOKUP(A8,Table3[],3, FALSE) -> 0.0017742501 | J8: =G8-I8 -> 0.074620253 | K8: =H8-I8 -> 0.011353945
A9: 2019-08 | B9: AAPL | C9: APPLE INC | D9: =Sheet1!A8/4 -> 52.185 | E9: 218.03 | F9: 192.58 | G9: =(D9-D8)/D8 -> -0.020184003 | H9: =VLOOKUP(A9,Table2[],3, FALSE) -> -0.018091653 | I9: =VLOOKUP(A9,Table3[],3, FALSE) -> 0.0017088473 | J9: =G9-I9 -> -0.02189285 | K9: =H9-I9 -> -0.0198005
A10: 2019-09 | B10: AAPL | C10: APPLE INC | D10: =Sheet1!A9/4 -> 55.9925 | E10: 226.42 | F10: 204.22 | G10: =(D10-D9)/D9 -> 0.072961579 | H10: =VLOOKUP(A10,Table2[],3, FALSE) -> 0.017181168 | I10: =VLOOKUP(A10,Table3[],3, FALSE) -> 0.0016433975 | J10: =G10-I10 -> 0.071318181 | K10: =H10-I10 -> 0.01553777
A11: 2019-10 | B11: AAPL | C11: APPLE INC | D11: =Sheet1!A10/4 -> 62.19 | E11: 249.75 | F11: 215.132 | G11: =(D11-D10)/D10 -> 0.11068447 | H11: =VLOOKUP(A11,Table2[],3, FALSE) -> 0.020431747 | I11: =VLOOKUP(A11,Table3[],3, FALSE) -> 0.0014303602 | J11: =G11-I11 -> 0.10925411 | K11: =H11-I11 -> 0.019001387
A12: 2019-11 | B12: AAPL | C12: APPLE INC | D12: =Sheet1!A11/4 -> 66.8125 | E12: 268 | F12: 249.16 | G12: =(D12-D11)/D11 -> 0.07432867 | H12: =VLOOKUP(A12,Table2[],3, FALSE) -> 0.034047064 | I12: =VLOOKUP(A12,Table3[],3, FALSE) -> 0.001307227 | J12: =G12-I12 -> 0.073021443 | K12: =H12-I12 -> 0.032739837
A13: 2019-12 | B13: AAPL | C13: APPLE INC | D13: =Sheet1!A12/4 -> 73.4125 | E13: 293.97 | F13: 256.29 | G13: =(D13-D12)/D12 -> 0.09878391 | H13: =VLOOKUP(A13,Table2[],3, FALSE) -> 0.028589803 | I13: =VLOOKUP(A13,Table3[],3, FALSE) -> 0.0012825803 | J13: =G13-I13 -> 0.09750133 | K13: =H13-I13 -> 0.027307223
A14: 2020-01 | B14: AAPL | C14: APPLE INC | D14: =Sheet1!A13/4 -> 77.3775 | E14: 327.85 | F14: 292.75 | G14: =(D14-D13)/D13 -> 0.054009876 | H14: =VLOOKUP(A14,Table2[],3, FALSE) -> -0.0016280898 | I14: =VLOOKUP(A14,Table3[],3, FALSE) -> 0.0012661455 | J14: =G14-I14 -> 0.05274373 | K14: =H14-I14 -> -0.0028942353
... A20: 2020-07 | B20: AAPL | C20: APPLE INC | D20: =Sheet1!A19/4 -> 106.26 | E20: 425.66 | F20: 356.58 | G20: =(D20-D19)/D19 -> 0.16513158 | H20: =VLOOKUP(A20,Table2[],3, FALSE) -> 0.055101297 | I20: =VLOOKUP(A20,Table3[],3, FALSE) -> 9.1620484e-05 | J20: =G20-I20 -> 0.16503996 | K20: =H20-I20 -> 0.055009676
A21: 2020-08 | B21: AAPL | C21: APPLE INC | D21: 129.04 | E21: 131 | F21: 107.8925 | G21: =(D21-D20)/D20 -> 0.21437982 | H21: =VLOOKUP(A21,Table2[],3, FALSE) -> 0.070064687 | I21: =VLOOKUP(A21,Table3[],3, FALSE) -> 6.6642235e-05 | J21: =G21-I21 -> 0.21431318 | K21: =H21-I21 -> 0.069998045
A22: 2020-09 | B22: AAPL | C22: APPLE INC | D22: 115.81 | E22: 137.98 | F22: 103.1 | G22: =(D22-D21)/D21 -> -0.10252635 | H22: =VLOOKUP(A22,Table2[],3, FALSE) -> -0.039227954 | I22: =VLOOKUP(A22,Table3[],3, FALSE) -> 7.496908e-05 | J22: =G22-I22 -> -0.10260132 | K22: =H22-I22 -> -0.039302923
A23: 2020-10 | B23: AAPL | C23: APPLE INC | D23: 108.86 | E23: 125.39 | F23: 107.72 | G23: =(D23-D22)/D22 -> -0.060012089 | H23: =VLOOKUP(A23,Table2[],3, FALSE) -> -0.027665775 | I23: =VLOOKUP(A23,Table3[],3, FALSE) -> 7.496908e-05 | J23: =G23-I23 -> -0.060087058 | K23: =H23-I23 -> -0.027740744
A24: 2020-11 | B24: AAPL | C24: APPLE INC | D24: 119.05 | E24: 121.99 | F24: 107.32 | G24: =(D24-D23)/D23 -> 0.093606467 | H24: =VLOOKUP(A24,Table2[],3, FALSE) -> 0.10754566 | I24: =VLOOKUP(A24,Table3[],3, FALSE) -> 7.496908e-05 | J24: =G24-I24 -> 0.093531498 | K24: =H24-I24 -> 0.10747069
A25: 2020-12 | B25: AAPL | C25: APPLE INC | D25: 132.69 | E25: 138.789 | F25: 120.01 | G25: =(D25-D24)/D24 -> 0.11457371 | H25: =VLOOKUP(A25,Table2[],3, FALSE) -> 0.037121407 | I25: =VLOOKUP(A25,Table3[],3, FALSE) -> 6.6642235e-05 | J25: =G25-I25 -> 0.11450707 | K25: =H25-I25 -> 0.037054764
A26: 2021-01 | B26: AAPL | C26: APPLE INC | D26: 131.96 | E26: 145.09 | F26: 126.382 | G26: =(D26-D25)/D25 -> -0.005501545 | H26: =VLOOKUP(A26,Table2[],3, FALSE) -> -0.01113664 | I26: =VLOOKUP(A26,Table3[],3, FALSE) -> 6.6642235e-05 | J26: =G26-I26 -> -0.0055681872 | K26: =H26-I26 -> -0.011203282
A27: 2021-02 | B27: AAPL | C27: APPLE INC | D27: 121.26 | E27: 137.877 | F27: 118.39 | G27: =(D27-D26)/D26 -> -0.081085177 | H27: =VLOOKUP(A27,Table2[],3, FALSE) -> 0.026091475 | I27: =VLOOKUP(A27,Table3[],3, FALSE) -> 3.3327224e-05 | J27: =G27-I27 -> -0.081118505 | K27: =H27-I27 -> 0.026058148
A28: 2021-03 | B28: AAPL | C28: APPLE INC | D28: 122.15 | E28: 128.72 | F28: 116.21 | G28: =(D28-D27)/D27 -> 0.0073396009 | H28: =VLOOKUP(A28,Table2[],3, FALSE) -> 0.042438634 | I28: =VLOOKUP(A28,Table3[],3, FALSE) -> 1.6665139e-05 | J28: =G28-I28 -> 0.0073229357 | K28: =H28-I28 -> 0.042421969
A29: 2021-04 | B29: AAPL | C29: APPLE INC | D29: 131.46 | E29: 137.07 | F29: 122.49 | G29: =(D29-D28)/D28 -> 0.076217765 | H29: =VLOOKUP(A29,Table2[],3, FALSE) -> 0.052425313 | I29: =VLOOKUP(A29,Table3[],3, FALSE) -> 1.6665139e-05 | J29: =G29-I29 -> 0.0762011 | K29: =H29-I29 -> 0.052408647
A30: 2021-05 | B30: AAPL | C30: APPLE INC | D30: 124.61 | E30: 134.07 | F30: 122.25 | G30: =(D30-D29)/D29 -> -0.052107105 | H30: =VLOOKUP(A30,Table2[],3, FALSE) -> 0.0054865026 | I30: =VLOOKUP(A30,Table3[],3, FALSE) -> 8.3329514e-06 | J30: =G30-I30 -> -0.052115438 | K30: =H30-I30 -> 0.0054781696
A31: 2021-06 | B31: AAPL | C31: APPLE INC | D31: 136.96 | E31: 137.41 | F31: 123.13 | G31: =(D31-D30)/D30 -> 0.099109221 | H31: =VLOOKUP(A31,Table2[],3, FALSE) -> 0.022213976 | I31: =VLOOKUP(A31,Table3[],3, FALSE) -> 2.4996563e-05 | J31: =G31-I31 -> 0.099084224 | K31: =H31-I31 -> 0.02218898
A32: 2021-07 | B32: AAPL | C32: APPLE INC | D32: 145.86 | E32: 150 | F32: 135.76 | G32: =(D32-D31)/D31 -> 0.064982477 | H32: =VLOOKUP(A32,Table2[],3, FALSE) -> 0.022748109 | I32: =VLOOKUP(A32,Table3[],3, FALSE) -> 4.1657121e-05 | J32: =G32-I32 -> 0.06494082 | K32: =H32-I32 -> 0.022706452
... A73: 2024-12 | B73: AAPL | C73: APPLE INC | D73: 250.42 | E73: 260.1 | F73: 237.16 | G73: =(D73-D72)/D72 -> 0.055155269 | H73: =VLOOKUP(A73,Table2[],3, FALSE) -> -0.024990137 | I73: =VLOOKUP(A73,Table3[],3, FALSE) -> 0.0036748094 | J73: =G73-I73 -> 0.05148046 | K73: =H73-I73 -> -0.028664946
A74: 2019-01 | B74: AMZN | C74: AMAZON.COM INC | D74: 1718.73 | E74: 1736.411 | F74: 1460.93 | H74: =VLOOKUP(A74,Table2[],3, FALSE) -> 0 | I74: =VLOOKUP(A74,Table3[],3, FALSE) -> 0.0019783315 | J74: =G74-I74 -> -0.0019783315 | K74: =H74-I74 -> -0.0019783315
A75: 2019-02 | B75: AMZN | C75: AMAZON.COM INC | D75: 1639.83 | E75: 1673.06 | F75: 1566.756 | G75: =(D75-D74)/D74 -> -0.045905989 | H75: =VLOOKUP(A75,Table2[],3, FALSE) -> 0.02972893 | I75: =VLOOKUP(A75,Table3[],3, FALSE) -> 0.0020027906 | J75: =G75-I75 -> -0.047908779 | K75: =H75-I75 -> 0.02772614
A76: 2019-03 | B76: AMZN | C76: AMAZON.COM INC | D76: 1780.75 | E76: 1823.75 | F76: 1586.57 | G76: =(D76-D75)/D75 -> 0.085935737 | H76: =VLOOKUP(A76,Table2[],3, FALSE) -> 0.017924288 | I76: =VLOOKUP(A76,Table3[],3, FALSE) -> 0.002019093 | J76: =G76-I76 -> 0.083916644 | K76: =H76-I76 -> 0.015905195
A77: 2019-04 | B77: AMZN | C77: AMAZON.COM INC | D77: 1926.52 | E77: 1956.335 | F77: 1798.73 | G77: =(D77-D76)/D76 -> 0.081858767 | H77: =VLOOKUP(A77,Table2[],3, FALSE) -> 0.039313435 | I77: =VLOOKUP(A77,Table3[],3, FALSE) -> 0.0020027906 | J77: =G77-I77 -> 0.079855977 | K77: =H77-I77 -> 0.037310644
A78: 2019-05 | B78: AMZN | C78: AMAZON.COM INC | D78: 1775.07 | E78: 1964.4 | F78: 1772.7034 | G78: =(D78-D77)/D77 -> -0.078613251 | H78: =VLOOKUP(A78,Table2[],3, FALSE) -> -0.065777726 | I78: =VLOOKUP(A78,Table3[],3, FALSE) -> 0.0019783315 | J78: =G78-I78 -> -0.080591582 | K78: =H78-I78 -> -0.067756058
A79: 2019-06 | B79: AMZN | C79: AMAZON.COM INC | D79: 1893.63 | E79: 1935.2 | F79: 1672 | G79: =(D79-D78)/D78 -> 0.066791732 | H79: =VLOOKUP(A79,Table2[],3, FALSE) -> 0.068930183 | I79: =VLOOKUP(A79,Table3[],3, FALSE) -> 0.001831439 | J79: =G79-I79 -> 0.064960293 | K79: =H79-I79 -> 0.067098744
A80: 2019-07 | B80: AMZN | C80: AMAZON.COM INC | D80: 1866.78 | E80: 2035.8 | F80: 1849.44 | G80: =(D80-D79)/D79 -> -0.014179116 | H80: =VLOOKUP(A80,Table2[],3, FALSE) -> 0.013128195 | I80: =VLOOKUP(A80,Table3[],3, FALSE) -> 0.0017742501 | J80: =G80-I80 -> -0.015953366 | K80: =H80-I80 -> 0.011353945
A81: 2019-08 | B81: AMZN | C81: AMAZON.COM INC | D81: 1776.29 | E81: 1897.92 | F81: 1743.51 | G81: =(D81-D80)/D80 -> -0.048473843 | H81: =VLOOKUP(A81,Table2[],3, FALSE) -> -0.018091653 | I81: =VLOOKUP(A81,Table3[],3, FALSE) -> 0.0017088473 | J81: =G81-I81 -> -0.05018269 | K81: =H81-I81 -> -0.0198005
A82: 2019-09 | B82: AMZN | C82: AMAZON.COM INC | D82: 1735.91 | E82: 1853.66 | F82: 1709.22 | G82: =(D82-D81)/D81 -> -0.022732774 | H82: =VLOOKUP(A82,Table2[],3, FALSE) -> 0.017181168 | I82: =VLOOKUP(A82,Table3[],3, FALSE) -> 0.0016433975 | J82: =G82-I82 -> -0.024376172 | K82: =H82-I82 -> 0.01553777
A83: 2019-10 | B83: AMZN | C83: AMAZON.COM INC | D83: 1776.66 | E83: 1798.85 | F83: 1685.06 | G83: =(D83-D82)/D82 -> 0.023474719 | H83: =VLOOKUP(A83,Table2[],3, FALSE) -> 0.020431747 | I83: =VLOOKUP(A83,Table3[],3, FALSE) -> 0.0014303602 | J83: =G83-I83 -> 0.022044359 | K83: =H83-I83 -> 0.019001387
A84: 2019-11 | B84: AMZN | C84: AMAZON.COM INC | D84: 1800.8 | E84: 1824.69 | F84: 1722.71 | G84: =(D84-D83)/D83 -> 0.013587293 | H84: =VLOOKUP(A84,Table2[],3, FALSE) -> 0.034047064 | I84: =VLOOKUP(A84,Table3[],3, FALSE) -> 0.001307227 | J84: =G84-I84 -> 0.012280066 | K84: =H84-I84 -> 0.032739837
A85: 2019-12 | B85: AMZN | C85: AMAZON.COM INC | D85: 1847.84 | E85: 1901.4 | F85: 1735 | G85: =(D85-D84)/D84 -> 0.026121724 | H85: =VLOOKUP(A85,Table2[],3, FALSE) -> 0.028589803 | I85: =VLOOKUP(A85,Table3[],3, FALSE) -> 0.0012825803 | J85: =G85-I85 -> 0.024839143 | K85: =H85-I85 -> 0.027307223
...

Sheet Sheet1
A1: 166.44
A2: 173.15
A3: 189.95
A4: 200.67
A5: 175.07
A6: 197.92
A7: 213.04
A8: 208.74
A9: 223.97
A10: 248.76
A11: 267.25
A12: 293.65
... A19: 425.04

Sheet Market Index
A1: Date | B1: Level of the S&P 500 Index | C1: Market return
A2: 2019-01 | B2: 2704.1
A3: 2019-02 | B3: 2784.49 | C3: =(B3-B2)/B2 -> 0.02972893
A4: 2019-03 | B4: 2834.4 | C4: =(B4-B3)/B3 -> 0.017924288
A5: 2019-04 | B5: 2945.83 | C5: =(B5-B4)/B4 -> 0.039313435
A6: 2019-05 | B6: 2752.06 | C6: =(B6-B5)/B5 -> -0.065777726
A7: 2019-06 | B7: 2941.76 | C7: =(B7-B6)/B6 -> 0.068930183
A8: 2019-07 | B8: 2980.38 | C8: =(B8-B7)/B7 -> 0.013128195
A9: 2019-08 | B9: 2926.46 | C9: =(B9-B8)/B8 -> -0.018091653
A10: 2019-09 | B10: 2976.74 | C10: =(B10-B9)/B9 -> 0.017181168
A11: 2019-10 | B11: 3037.56 | C11: =(B11-B10)/B10 -> 0.020431747
A12: 2019-11 | B12: 3140.98 | C12: =(B12-B11)/B11 -> 0.034047064
A13: 2019-12 | B13: 3230.78 | C13: =(B13-B12)/B12 -> 0.028589803
A14: 2020-01 | B14: 3225.52 | C14: =(B14-B13)/B13 -> -0.0016280898
... A73: 2024-12 | B73: 5881.63 | C73: =(B73-B72)/B72 -> -0.024990137

Sheet Risk Free Rate
A1: Date | B1: Return on the T bill (in %) | C1: Risk Free rate monthly
A2: 2019-01 | B2: 2.4 | C2: =((1+(B2/100))^(1/12))-1 -> 0.0019783315
A3: 2019-02 | B3: 2.43 | C3: =((1+(B3/100))^(1/12))-1 -> 0.0020027906
A4: 2019-03 | B4: 2.45 | C4: =((1+(B4/100))^(1/12))-1 -> 0.002019093
A5: 2019-04 | B5: 2.43 | C5: =((1+(B5/100))^(1/12))-1 -> 0.0020027906
A6: 2019-05 | B6: 2.4 | C6: =((1+(B6/100))^(1/12))-1 -> 0.0019783315
A7: 2019-06 | B7: 2.22 | C7: =((1+(B7/100))^(1/12))-1 -> 0.001831439
A8: 2019-07 | B8: 2.15 | C8: =((1+(B8/100))^(1/12))-1 -> 0.0017742501
A9: 2019-08 | B9: 2.07 | C9: =((1+(B9/100))^(1/12))-1 -> 0.0017088473
A10: 2019-09 | B10: 1.99 | C10: =((1+(B10/100))^(1/12))-1 -> 0.0016433975
A11: 2019-10 | B11: 1.73 | C11: =((1+(B11/100))^(1/12))-1 -> 0.0014303602
A12: 2019-11 | B12: 1.58 | C12: =((1+(B12/100))^(1/12))-1 -> 0.001307227
A13: 2019-12 | B13: 1.55 | C13: =((1+(B13/100))^(1/12))-1 -> 0.0012825803
... A73: 2024-12 | B73: 4.5 | C73: =((1+(B73/100))^(1/12))-1 -> 0.0036748094

Sheet sharp ratio
J5: EXCESS RETURN
D8: Sum of Excess Return | E8: Company Name
D9: Date | E9: AMAZON.COM INC | F9: APPLE INC | G9: GE AEROSPACE | H9: Grand Total | J9: AMAZON.COM INC | K9: APPLE INC | L9: GE AEROSPACE | O9: AMAZON.COM INC | P9: APPLE INC | Q9: GE AEROSPACE
D10: 2019-02 | E10: -0.047908779 | F10: 0.038312038 | G10: 0.020635005 | H10: 0.011038263 | J10: -0.047908779 | K10: 0.038312038 | L10: 0.020635005 | N10: mean | O10: =AVERAGE(J10:J80) -> 0.015161004 | P10: =AVERAGE(K10:K80) -> 0.026890056 | Q10: =AVERAGE(L10:L80) -> 0.013736478
D11: 2019-03 | E11: 0.083916644 | F11: 0.095006607 | G11: -0.040517649 | H11: 0.1384056 | J11: 0.083916644 | K11: 0.095006607 | L11: -0.040517649 | N11: std | O11: =_xlfn.STDEV.S(J10:J80) -> 0.089491083 | P11: =_xlfn.STDEV.S(K10:K80) -> 0.082388955 | Q11: =_xlfn.STDEV.S(L10:L80) -> 0.10626434
D12: 2019-04 | E12: 0.079855977 | F12: 0.054433114 | G12: 0.016015227 | H12: 0.15030432 | J12: 0.079855977 | K12: 0.054433114 | L12: 0.016015227 | N12: sharp | O12: =O10/O11 -> 0.16941357 | P12: =P10/P11 -> 0.32637938 | Q12: =Q10/Q11 -> 0.12926705
D13: 2019-05 | E13: -0.080591582 | F13: -0.12955096 | G13: -0.073758076 | H13: -0.28390062 | J13: -0.080591582 | K13: -0.12955096 | L13: -0.073758076
D14: 2019-06 | E14: 0.064960293 | F14: 0.12868778 | G14: 0.1104567 | H14: 0.30410477 | J14: 0.064960293 | K14: 0.12868778 | L14: 0.1104567 | O14: =0.2651*SQRT(12) -> 0.91833334
D15: 2019-07 | E15: -0.015953366 | F15: 0.074620253 | G15: -0.0065361548 | H15: 0.052130732 | J15: -0.015953366 | K15: 0.074620253 | L15: -0.0065361548
D16: 2019-08 | E16: -0.05018269 | F16: -0.02189285 | G16: -0.21223516 | H16: -0.2843107 | J16: -0.05018269 | K16: -0.02189285 | L16: -0.21223516
D17: 2019-09 | E17: -0.024376172 | F17: 0.071318181 | G17: 0.081992966 | H17: 0.12893498 | J17: -0.024376172 | K17: 0.071318181 | L17: 0.081992966
D18: 2019-10 | E18: 0.022044359 | F18: 0.10925411 | G18: 0.11490074 | H18: 0.2461992 | J18: 0.022044359 | K18: 0.10925411 | L18: 0.11490074
D19: 2019-11 | E19: 0.012280066 | F19: 0.073021443 | G19: 0.12795129 | H19: 0.2132528 | J19: 0.012280066 | K19: 0.073021443 | L19: 0.12795129
D20: 2019-12 | E20: 0.024839143 | F20: 0.09750133 | G20: -0.011043006 | H20: 0.11129747 | J20: 0.024839143 | K20: 0.09750133 | L20: -0.011043006
D21: 2020-01 | E21: 0.08579767 | F21: 0.05274373 | G21: 0.11432525 | H21: 0.25286665 | J21: 0.08579767 | K21: 0.05274373 | L21: 0.11432525
D22: 2020-02 | E22: -0.063520975 | F22: -0.11810475 | G22: -0.12741164 | H22: -0.30903737 | J22: -0.063520975 | K22: -0.11810475 | L22: -0.12741164
D23: 2020-03 | E23: 0.034712759 | F23: -0.070069298 | G23: -0.2705284 | H23: -0.30588494 | J23: 0.034712759 | K23: -0.070069298 | L23: -0.2705284
D24: 2020-04 | E24: 0.26880853 | F24: 0.15528217 | G24: -0.14366845 | H24: 0.28042225 | J24: 0.26880853 | K24: 0.15528217 | L24: -0.14366845
D25: 2020-05 | E25: -0.012868259 | F25: 0.082081443 | G25: -0.033906825 | H25: 0.035306359 | J25: -0.012868259 | K25: 0.082081443 | L25: -0.033906825
D26: 2020-06 | E26: 0.1294585 | F26: 0.14727803 | G26: 0.039465552 | H26: 0.31620209 | J26: 0.1294585 | K26: 0.14727803 | L26: 0.039465552
... D80: 2024-12 | E80: 0.051642907 | F80: 0.05148046 | G80: -0.088051182 | H80: 0.015072185 | J80: 0.051642907 | K80: 0.05148046 | L80: -0.088051182
D81: Grand Total | E81: 1.0764313 | F81: 1.909194 | G81: 0.97528995 | H81: 3.9609152
